Workbook
Name BED_CAP_CARROT: Inputs!$C$17
Name BED_CAP_MESCLUN: Inputs!$C$22
Name BED_CAP_TOMATO: Inputs!$C$12
Name DIM_PCT_CARROT: Inputs!$C$21
Name DIM_PCT_MESCLUN: Inputs!$C$26
Name DIM_PCT_TOMATO: Inputs!$C$16
Name FARMER_HOURS: Inputs!$C$7
Name FARMER_WAGE: Inputs!$C$8
Name FERT_CARROT: Inputs!$C$20
Name FERT_MESCLUN: Inputs!$C$25
Name FERT_TOMATO: Inputs!$C$15
Name FIXED_COST: Inputs!$C$6
Name HRS_PER_BED_CARROT: Inputs!$C$19
Name HRS_PER_BED_MESCLUN: Inputs!$C$24
Name HRS_PER_BED_TOMATO: Inputs!$C$14
Name LABOR_MODE: Inputs!$C$28
Name PRICE_CARROT: Inputs!$C$18
Name PRICE_MESCLUN: Inputs!$C$23
Name PRICE_TOMATO: Inputs!$C$13
Name PROFIT: Optimization!$B$22
Name TEMP_HOURS_PER_WORKER: Inputs!$C$10
Name TEMP_WAGE: Inputs!$C$11
Name TEMP_WORKERS_MAX: Inputs!$C$9
Name TOTAL_BEDS: Inputs!$C$5
Name WEEKS: Inputs!$C$4

Sheet Inputs
A1: Marginal Analysis — Market Garden: Inputs
A3: Group | B3: Name | C3: Value | D3: Unit | E3: Source
A4: Farm | B4: WEEKS | C4: 36 | D4: weeks | E4: case scenario table
A5: Farm | B5: TOTAL_BEDS | C5: 64 | D5: beds | E5: case scenario table
A6: Farm | B6: FIXED_COST | C6: 20000 | D6: $ | E6: case scenario table
A7: Farm | B7: FARMER_HOURS | C7: 720 | D7: hrs | E7: case scenario table
A8: Farm | B8: FARMER_WAGE | C8: 34.72 | D8: $/hr | E8: case scenario table
A9: Farm | B9: TEMP_WORKERS_MAX | C9: 4 | D9: count | E9: case scenario table
A10: Farm | B10: TEMP_HOURS_PER_WORKER | C10: 1440 | D10: hrs | E10: case scenario table
A11: Farm | B11: TEMP_WAGE | C11: 17.36 | D11: $/hr | E11: case scenario table
A12: Tomato | B12: BED_CAP_TOMATO | C12: 20 | D12: beds | E12: case scenario table
A13: Tomato | B13: PRICE_TOMATO | C13: 8800 | D13: $/bed | E13: case scenario table
A14: Tomato | B14: HRS_PER_BED_TOMATO | C14: 2.5 | D14: hrs/week/bed | E14: case scenario table
A15: Tomato | B15: FERT_TOMATO | C15: 880 | D15: $/bed | E15: case scenario table
... A28: Switch | B28: LABOR_MODE | C28: 1 | D28: 1 = fractional temp hours; 2 = whole workers | E28: modeling choice (agreed with user)

Sheet Labor
A1: Labor Hours by Bed Count
A3: LABOR_HRS_CROP(q) = q × HRS_PER_BED_CROP × WEEKS × (1 + DIM_PCT_CROP)^q | G3: Farm summary at current bed counts
A4: q (beds) | B4: Tomato hrs | C4: Carrot hrs | D4: Mesclun hrs | G4: Beds — Tomatoes | H4: =Optimization!$B$5 -> 10
A5: 0 | B5: =IF($A5>BED_CAP_TOMATO,"",$A5*HRS_PER_BED_TOMATO*WEEKS*(1+DIM_PCT_TOMATO)^$A5) -> 0 | C5: =IF($A5>BED_CAP_CARROT,"",$A5*HRS_PER_BED_CARROT*WEEKS*(1+DIM_PCT_CARROT)^$A5) -> 0 | D5: =IF($A5>BED_CAP_MESCLUN,"",$A5*HRS_PER_BED_MESCLUN*WEEKS*(1+DIM_PCT_MESCLUN)^$A5) -> 0 | G5: Beds — Carrots | H5: =Optimization!$B$6 -> 20
A6: 1 | B6: =IF($A6>BED_CAP_TOMATO,"",$A6*HRS_PER_BED_TOMATO*WEEKS*(1+DIM_PCT_TOMATO)^$A6) -> 99 | C6: =IF($A6>BED_CAP_CARROT,"",$A6*HRS_PER_BED_CARROT*WEEKS*(1+DIM_PCT_CARROT)^$A6) -> 30.7377 | D6: =IF($A6>BED_CAP_MESCLUN,"",$A6*HRS_PER_BED_MESCLUN*WEEKS*(1+DIM_PCT_MESCLUN)^$A6) -> 45.5625 | G6: Beds — Mesclun | H6: =Optimization!$B$7 -> 30
A7: 2 | B7: =IF($A7>BED_CAP_TOMATO,"",$A7*HRS_PER_BED_TOMATO*WEEKS*(1+DIM_PCT_TOMATO)^$A7) -> 217.8 | C7: =IF($A7>BED_CAP_CARROT,"",$A7*HRS_PER_BED_CARROT*WEEKS*(1+DIM_PCT_CARROT)^$A7) -> 63.012285 | D7: =IF($A7>BED_CAP_MESCLUN,"",$A7*HRS_PER_BED_MESCLUN*WEEKS*(1+DIM_PCT_MESCLUN)^$A7) -> 92.264062 | G7: Labor hrs — Tomatoes | H7: =$H$4*HRS_PER_BED_TOMATO*WEEKS*(1+DIM_PCT_TOMATO)^$H$4 -> 2334.3682
A8: 3 | B8: =IF($A8>BED_CAP_TOMATO,"",$A8*HRS_PER_BED_TOMATO*WEEKS*(1+DIM_PCT_TOMATO)^$A8) -> 359.37 | C8: =IF($A8>BED_CAP_CARROT,"",$A8*HRS_PER_BED_CARROT*WEEKS*(1+DIM_PCT_CARROT)^$A8) -> 96.881388 | D8: =IF($A8>BED_CAP_MESCLUN,"",$A8*HRS_PER_BED_MESCLUN*WEEKS*(1+DIM_PCT_MESCLUN)^$A8) -> 140.12604 | G8: Labor hrs — Carrots | H8: =$H$5*HRS_PER_BED_CARROT*WEEKS*(1+DIM_PCT_CARROT)^$H$5 -> 982.7766
A9: 4 | B9: =IF($A9>BED_CAP_TOMATO,"",$A9*HRS_PER_BED_TOMATO*WEEKS*(1+DIM_PCT_TOMATO)^$A9) -> 527.076 | C9: =IF($A9>BED_CAP_CARROT,"",$A9*HRS_PER_BED_CARROT*WEEKS*(1+DIM_PCT_CARROT)^$A9) -> 132.40456 | D9: =IF($A9>BED_CAP_MESCLUN,"",$A9*HRS_PER_BED_MESCLUN*WEEKS*(1+DIM_PCT_MESCLUN)^$A9) -> 189.17016 | G9: Labor hrs — Mesclun | H9: =$H$6*HRS_PER_BED_MESCLUN*WEEKS*(1+DIM_PCT_MESCLUN)^$H$6 -> 1959.678
A10: 5 | B10: =IF($A10>BED_CAP_TOMATO,"",$A10*HRS_PER_BED_TOMATO*WEEKS*(1+DIM_PCT_TOMATO)^$A10) -> 724.7295 | C10: =IF($A10>BED_CAP_CARROT,"",$A10*HRS_PER_BED_CARROT*WEEKS*(1+DIM_PCT_CARROT)^$A10) -> 169.64335 | D10: =IF($A10>BED_CAP_MESCLUN,"",$A10*HRS_PER_BED_MESCLUN*WEEKS*(1+DIM_PCT_MESCLUN)^$A10) -> 239.41848 | G10: Total labor hours | H10: =SUM($H$7:$H$9) -> 5276.8228
A11: 6 | B11: =IF($A11>BED_CAP_TOMATO,"",$A11*HRS_PER_BED_TOMATO*WEEKS*(1+DIM_PCT_TOMATO)^$A11) -> 956.64294 | C11: =IF($A11>BED_CAP_CARROT,"",$A11*HRS_PER_BED_CARROT*WEEKS*(1+DIM_PCT_CARROT)^$A11) -> 208.66132 | D11: =IF($A11>BED_CAP_MESCLUN,"",$A11*HRS_PER_BED_MESCLUN*WEEKS*(1+DIM_PCT_MESCLUN)^$A11) -> 290.89346 | G11: Farmer hours used | H11: =MIN($H$10,FARMER_HOURS) -> 720
A12: 7 | B12: =IF($A12>BED_CAP_TOMATO,"",$A12*HRS_PER_BED_TOMATO*WEEKS*(1+DIM_PCT_TOMATO)^$A12) -> 1227.6918 | C12: =IF($A12>BED_CAP_CARROT,"",$A12*HRS_PER_BED_CARROT*WEEKS*(1+DIM_PCT_CARROT)^$A12) -> 249.52416 | D12: =IF($A12>BED_CAP_MESCLUN,"",$A12*HRS_PER_BED_MESCLUN*WEEKS*(1+DIM_PCT_MESCLUN)^$A12) -> 343.6179 | G12: Temp hours required | H12: =MAX(0,$H$10-FARMER_HOURS) -> 4556.8228
A13: 8 | B13: =IF($A13>BED_CAP_TOMATO,"",$A13*HRS_PER_BED_TOMATO*WEEKS*(1+DIM_PCT_TOMATO)^$A13) -> 1543.3839 | C13: =IF($A13>BED_CAP_CARROT,"",$A13*HRS_PER_BED_CARROT*WEEKS*(1+DIM_PCT_CARROT)^$A13) -> 292.29973 | D13: =IF($A13>BED_CAP_MESCLUN,"",$A13*HRS_PER_BED_MESCLUN*WEEKS*(1+DIM_PCT_MESCLUN)^$A13) -> 397.615 | G13: Temp workers required (fractional) | H13: =$H$12/TEMP_HOURS_PER_WORKER -> 3.1644603
A14: 9 | B14: =IF($A14>BED_CAP_TOMATO,"",$A14*HRS_PER_BED_TOMATO*WEEKS*(1+DIM_PCT_TOMATO)^$A14) -> 1909.9376 | C14: =IF($A14>BED_CAP_CARROT,"",$A14*HRS_PER_BED_CARROT*WEEKS*(1+DIM_PCT_CARROT)^$A14) -> 337.05812 | D14: =IF($A14>BED_CAP_MESCLUN,"",$A14*HRS_PER_BED_MESCLUN*WEEKS*(1+DIM_PCT_MESCLUN)^$A14) -> 452.90833 | G14: Temp workers billed | H14: =IF(LABOR_MODE=1,$H$13,ROUNDUP($H$13,0)) -> 3.1644603
A15: 10 | B15: =IF($A15>BED_CAP_TOMATO,"",$A15*HRS_PER_BED_TOMATO*WEEKS*(1+DIM_PCT_TOMATO)^$A15) -> 2334.3682 | C15: =IF($A15>BED_CAP_CARROT,"",$A15*HRS_PER_BED_CARROT*WEEKS*(1+DIM_PCT_CARROT)^$A15) -> 383.87175 | D15: =IF($A15>BED_CAP_MESCLUN,"",$A15*HRS_PER_BED_MESCLUN*WEEKS*(1+DIM_PCT_MESCLUN)^$A15) -> 509.52187 | G15: Temp hours billed | H15: =IF(LABOR_MODE=1,$H$12,$H$14*TEMP_HOURS_PER_WORKER) -> 4556.8228
A16: 11 | B16: =IF($A16>BED_CAP_TOMATO,"",$A16*HRS_PER_BED_TOMATO*WEEKS*(1+DIM_PCT_TOMATO)^$A16) -> 2824.5855 | C16: =IF($A16>BED_CAP_CARROT,"",$A16*HRS_PER_BED_CARROT*WEEKS*(1+DIM_PCT_CARROT)^$A16) -> 432.8154 | D16: =IF($A16>BED_CAP_MESCLUN,"",$A16*HRS_PER_BED_MESCLUN*WEEKS*(1+DIM_PCT_MESCLUN)^$A16) -> 567.47999 | G16: Farmer labor $ | H16: =$H$11*FARMER_WAGE -> 24998.4
A17: 12 | B17: =IF($A17>BED_CAP_TOMATO,"",$A17*HRS_PER_BED_TOMATO*WEEKS*(1+DIM_PCT_TOMATO)^$A17) -> 3389.5026 | C17: =IF($A17>BED_CAP_CARROT,"",$A17*HRS_PER_BED_CARROT*WEEKS*(1+DIM_PCT_CARROT)^$A17) -> 483.96631 | D17: =IF($A17>BED_CAP_MESCLUN,"",$A17*HRS_PER_BED_MESCLUN*WEEKS*(1+DIM_PCT_MESCLUN)^$A17) -> 626.80744 | G17: Temp labor $ | H17: =$H$15*TEMP_WAGE -> 79106.445
A18: 13 | B18: =IF($A18>BED_CAP_TOMATO,"",$A18*HRS_PER_BED_TOMATO*WEEKS*(1+DIM_PCT_TOMATO)^$A18) -> 4039.1573 | C18: =IF($A18>BED_CAP_CARROT,"",$A18*HRS_PER_BED_CARROT*WEEKS*(1+DIM_PCT_CARROT)^$A18) -> 537.40426 | D18: =IF($A18>BED_CAP_MESCLUN,"",$A18*HRS_PER_BED_MESCLUN*WEEKS*(1+DIM_PCT_MESCLUN)^$A18) -> 687.52941 | G18: Total labor $ | H18: =$H$16+$H$17 -> 104104.84
A19: 14 | B19: =IF($A19>BED_CAP_TOMATO,"",$A19*HRS_PER_BED_TOMATO*WEEKS*(1+DIM_PCT_TOMATO)^$A19) -> 4784.8479 | C19: =IF($A19>BED_CAP_CARROT,"",$A19*HRS_PER_BED_CARROT*WEEKS*(1+DIM_PCT_CARROT)^$A19) -> 593.21163 | D19: =IF($A19>BED_CAP_MESCLUN,"",$A19*HRS_PER_BED_MESCLUN*WEEKS*(1+DIM_PCT_MESCLUN)^$A19) -> 749.67149 | G19: Blended labor rate ($/hr) | H19: =IF($H$10=0,0,$H$18/$H$10) -> 19.728698
A20: 15 | B20: =IF($A20>BED_CAP_TOMATO,"",$A20*HRS_PER_BED_TOMATO*WEEKS*(1+DIM_PCT_TOMATO)^$A20) -> 5639.285 | C20: =IF($A20>BED_CAP_CARROT,"",$A20*HRS_PER_BED_CARROT*WEEKS*(1+DIM_PCT_CARROT)^$A20) -> 651.47348 | D20: =IF($A20>BED_CAP_MESCLUN,"",$A20*HRS_PER_BED_MESCLUN*WEEKS*(1+DIM_PCT_MESCLUN)^$A20) -> 813.2597
A21: 16 | B21: =IF($A21>BED_CAP_TOMATO,"",$A21*HRS_PER_BED_TOMATO*WEEKS*(1+DIM_PCT_TOMATO)^$A21) -> 6616.7611 | C21: =IF($A21>BED_CAP_CARROT,"",$A21*HRS_PER_BED_CARROT*WEEKS*(1+DIM_PCT_CARROT)^$A21) -> 712.27767 | D21: =IF($A21>BED_CAP_MESCLUN,"",$A21*HRS_PER_BED_MESCLUN*WEEKS*(1+DIM_PCT_MESCLUN)^$A21) -> 878.32047
A22: 17 | B22: =IF($A22>BED_CAP_TOMATO,"",$A22*HRS_PER_BED_TOMATO*WEEKS*(1+DIM_PCT_TOMATO)^$A22) -> 7733.3395 | C22: =IF($A22>BED_CAP_CARROT,"",$A22*HRS_PER_BED_CARROT*WEEKS*(1+DIM_PCT_CARROT)^$A22) -> 775.7149 | D22: =IF($A22>BED_CAP_MESCLUN,"",$A22*HRS_PER_BED_MESCLUN*WEEKS*(1+DIM_PCT_MESCLUN)^$A22) -> 944.8807
A23: 18 | B23: =IF($A23>BED_CAP_TOMATO,"",$A23*HRS_PER_BED_TOMATO*WEEKS*(1+DIM_PCT_TOMATO)^$A23) -> 9007.066 | C23: =IF($A23>BED_CAP_CARROT,"",$A23*HRS_PER_BED_CARROT*WEEKS*(1+DIM_PCT_CARROT)^$A23) -> 841.87882 | D23: =IF($A23>BED_CAP_MESCLUN,"",$A23*HRS_PER_BED_MESCLUN*WEEKS*(1+DIM_PCT_MESCLUN)^$A23) -> 1012.9677
A24: 19 | B24: =IF($A24>BED_CAP_TOMATO,"",$A24*HRS_PER_BED_TOMATO*WEEKS*(1+DIM_PCT_TOMATO)^$A24) -> 10458.204 | C24: =IF($A24>BED_CAP_CARROT,"",$A24*HRS_PER_BED_CARROT*WEEKS*(1+DIM_PCT_CARROT)^$A24) -> 910.86611 | D24: =IF($A24>BED_CAP_MESCLUN,"",$A24*HRS_PER_BED_MESCLUN*WEEKS*(1+DIM_PCT_MESCLUN)^$A24) -> 1082.6092
A25: 20 | B25: =IF($A25>BED_CAP_TOMATO,"",$A25*HRS_PER_BED_TOMATO*WEEKS*(1+DIM_PCT_TOMATO)^$A25) -> 12109.5 | C25: =IF($A25>BED_CAP_CARROT,"",$A25*HRS_PER_BED_CARROT*WEEKS*(1+DIM_PCT_CARROT)^$A25) -> 982.7766 | D25: =IF($A25>BED_CAP_MESCLUN,"",$A25*HRS_PER_BED_MESCLUN*WEEKS*(1+DIM_PCT_MESCLUN)^$A25) -> 1153.8335
A26: 21 | B26: =IF($A26>BED_CAP_TOMATO,"",$A26*HRS_PER_BED_TOMATO*WEEKS*(1+DIM_PCT_TOMATO)^$A26) | C26: =IF($A26>BED_CAP_CARROT,"",$A26*HRS_PER_BED_CARROT*WEEKS*(1+DIM_PCT_CARROT)^$A26) | D26: =IF($A26>BED_CAP_MESCLUN,"",$A26*HRS_PER_BED_MESCLUN*WEEKS*(1+DIM_PCT_MESCLUN)^$A26) -> 1226.6692
A27: 22 | B27: =IF($A27>BED_CAP_TOMATO,"",$A27*HRS_PER_BED_TOMATO*WEEKS*(1+DIM_PCT_TOMATO)^$A27) | C27: =IF($A27>BED_CAP_CARROT,"",$A27*HRS_PER_BED_CARROT*WEEKS*(1+DIM_PCT_CARROT)^$A27) | D27: =IF($A27>BED_CAP_MESCLUN,"",$A27*HRS_PER_BED_MESCLUN*WEEKS*(1+DIM_PCT_MESCLUN)^$A27) -> 1301.1456
A28: 23 | B28: =IF($A28>BED_CAP_TOMATO,"",$A28*HRS_PER_BED_TOMATO*WEEKS*(1+DIM_PCT_TOMATO)^$A28) | C28: =IF($A28>BED_CAP_CARROT,"",$A28*HRS_PER_BED_CARROT*WEEKS*(1+DIM_PCT_CARROT)^$A28) | D28: =IF($A28>BED_CAP_MESCLUN,"",$A28*HRS_PER_BED_MESCLUN*WEEKS*(1+DIM_PCT_MESCLUN)^$A28) -> 1377.2922
A29: 24 | B29: =IF($A29>BED_CAP_TOMATO,"",$A29*HRS_PER_BED_TOMATO*WEEKS*(1+DIM_PCT_TOMATO)^$A29) | C29: =IF($A29>BED_CAP_CARROT,"",$A29*HRS_PER_BED_CARROT*WEEKS*(1+DIM_PCT_CARROT)^$A29) | D29: =IF($A29>BED_CAP_MESCLUN,"",$A29*HRS_PER_BED_MESCLUN*WEEKS*(1+DIM_PCT_MESCLUN)^$A29) -> 1455.1391
A30: 25 | B30: =IF($A30>BED_CAP_TOMATO,"",$A30*HRS_PER_BED_TOMATO*WEEKS*(1+DIM_PCT_TOMATO)^$A30) | C30: =IF($A30>BED_CAP_CARROT,"",$A30*HRS_PER_BED_CARROT*WEEKS*(1+DIM_PCT_CARROT)^$A30) | D30: =IF($A30>BED_CAP_MESCLUN,"",$A30*HRS_PER_BED_MESCLUN*WEEKS*(1+DIM_PCT_MESCLUN)^$A30) -> 1534.7171
A31: 26 | B31: =IF($A31>BED_CAP_TOMATO,"",$A31*HRS_PER_BED_TOMATO*WEEKS*(1+DIM_PCT_TOMATO)^$A31) | C31: =IF($A31>BED_CAP_CARROT,"",$A31*HRS_PER_BED_CARROT*WEEKS*(1+DIM_PCT_CARROT)^$A31) | D31: =IF($A31>BED_CAP_MESCLUN,"",$A31*HRS_PER_BED_MESCLUN*WEEKS*(1+DIM_PCT_MESCLUN)^$A31) -> 1616.0571
... A36: 31 | B36: =IF($A36>BED_CAP_TOMATO,"",$A36*HRS_PER_BED_TOMATO*WEEKS*(1+DIM_PCT_TOMATO)^$A36) | C36: =IF($A36>BED_CAP_CARROT,"",$A36*HRS_PER_BED_CARROT*WEEKS*(1+DIM_PCT_CARROT)^$A36) | D36: =IF($A36>BED_CAP_MESCLUN,"",$A36*HRS_PER_BED_MESCLUN*WEEKS*(1+DIM_PCT_MESCLUN)^$A36)

Sheet Cost
A1: Cost, Revenue & Marginal Cost — Standalone (crop alone on the farm) | N1: Marginal Cost at the Optimum (other two crops held at their solved bed counts)
A2: Each block assumes the other two crops are at 0 beds, so the farmer's 720 hrs are applied entirely to this crop. | N2: MC labor = change in TOTAL farm labor $ when this crop moves from q−1 to q beds, priced under the farm-wide blended rate. Rows extend to cap+1 for the shadow price.
A3: Tomatoes — standalone | N3: Tomatoes — at the optimum
A4: q (beds) | B4: Labor hrs | C4: Farmer hrs | D4: Temp hrs | E4: Labor $ | F4: Blended $/hr | G4: Fertilizer $ | H4: Revenue $ | I4: MC labor $/bed | J4: MC total $/bed | K4: Price − MC | L4: Standalone profit | N4: q (beds) | O4: This crop hrs | P4: Other crops hrs | Q4: Total farm hrs | R4: Temp hrs | S4: Total farm labor $ | T4: MC labor $/bed | U4: MC total $/bed | V4: Price − MC
A5: 0 | B5: {=INDEX(Labor!$B$5:$B$36,$A5+1)} -> 0 | C5: =MIN($B5,FARMER_HOURS) -> 0 | D5: =MAX(0,$B5-FARMER_HOURS) -> 0 | E5: =$C5*FARMER_WAGE+IF(LABOR_MODE=1,$D5,ROUNDUP($D5/TEMP_HOURS_PER_WORKER,0)*TEMP_HOURS_PER_WORKER)*TEMP_WAGE -> 0 | F5: =IF($B5=0,0,$E5/$B5) -> 0 | G5: =$A5*FERT_TOMATO -> 0 | H5: =$A5*PRICE_TOMATO -> 0 | I5: =IF($A5=0,"",$E5-$E4) | J5: =IF($A5=0,"",$I5+FERT_TOMATO) | K5: =IF($A5=0,"",PRICE_TOMATO-$J5) | L5: =$H5-$E5-$G5-FIXED_COST -> -20000 | N5: 0 | O5: =$N5*HRS_PER_BED_TOMATO*WEEKS*(1+DIM_PCT_TOMATO)^$N5 -> 0 | P5: =Labor!$H$8+Labor!$H$9 -> 2942.4546 | Q5: =$O5+$P5 -> 2942.4546 | R5: =MAX(0,$Q5-FARMER_HOURS) -> 2222.4546 | S5: =MIN($Q5,FARMER_HOURS)*FARMER_WAGE+IF(LABOR_MODE=1,$R5,ROUNDUP($R5/TEMP_HOURS_PER_WORKER,0)*TEMP_HOURS_PER_WORKER)*TEMP_WAGE -> 63580.212 | T5: =IF($N5=0,"",$S5-$S4) | U5: =IF($N5=0,"",$T5+FERT_TOMATO) | V5: =IF($N5=0,"",PRICE_TOMATO-$U5)
A6: 1 | B6: {=INDEX(Labor!$B$5:$B$36,$A6+1)} -> 99 | C6: =MIN($B6,FARMER_HOURS) -> 99 | D6: =MAX(0,$B6-FARMER_HOURS) -> 0 | E6: =$C6*FARMER_WAGE+IF(LABOR_MODE=1,$D6,ROUNDUP($D6/TEMP_HOURS_PER_WORKER,0)*TEMP_HOURS_PER_WORKER)*TEMP_WAGE -> 3437.28 | F6: =IF($B6=0,0,$E6/$B6) -> 34.72 | G6: =$A6*FERT_TOMATO -> 880 | H6: =$A6*PRICE_TOMATO -> 8800 | I6: =IF($A6=0,"",$E6-$E5) -> 3437.28 | J6: =IF($A6=0,"",$I6+FERT_TOMATO) -> 4317.28 | K6: =IF($A6=0,"",PRICE_TOMATO-$J6) -> 4482.72 | L6: =$H6-$E6-$G6-FIXED_COST -> -15517.28 | N6: 1 | O6: =$N6*HRS_PER_BED_TOMATO*WEEKS*(1+DIM_PCT_TOMATO)^$N6 -> 99 | P6: =Labor!$H$8+Labor!$H$9 -> 2942.4546 | Q6: =$O6+$P6 -> 3041.4546 | R6: =MAX(0,$Q6-FARMER_HOURS) -> 2321.4546 | S6: =MIN($Q6,FARMER_HOURS)*FARMER_WAGE+IF(LABOR_MODE=1,$R6,ROUNDUP($R6/TEMP_HOURS_PER_WORKER,0)*TEMP_HOURS_PER_WORKER)*TEMP_WAGE -> 65298.852 | T6: =IF($N6=0,"",$S6-$S5) -> 1718.64 | U6: =IF($N6=0,"",$T6+FERT_TOMATO) -> 2598.64 | V6: =IF($N6=0,"",PRICE_TOMATO-$U6) -> 6201.36
A7: 2 | B7: {=INDEX(Labor!$B$5:$B$36,$A7+1)} -> 217.8 | C7: =MIN($B7,FARMER_HOURS) -> 217.8 | D7: =MAX(0,$B7-FARMER_HOURS) -> 0 | E7: =$C7*FARMER_WAGE+IF(LABOR_MODE=1,$D7,ROUNDUP($D7/TEMP_HOURS_PER_WORKER,0)*TEMP_HOURS_PER_WORKER)*TEMP_WAGE -> 7562.016 | F7: =IF($B7=0,0,$E7/$B7) -> 34.72 | G7: =$A7*FERT_TOMATO -> 1760 | H7: =$A7*PRICE_TOMATO -> 17600 | I7: =IF($A7=0,"",$E7-$E6) -> 4124.736 | J7: =IF($A7=0,"",$I7+FERT_TOMATO) -> 5004.736 | K7: =IF($A7=0,"",PRICE_TOMATO-$J7) -> 3795.264 | L7: =$H7-$E7-$G7-FIXED_COST -> -11722.016 | N7: 2 | O7: =$N7*HRS_PER_BED_TOMATO*WEEKS*(1+DIM_PCT_TOMATO)^$N7 -> 217.8 | P7: =Labor!$H$8+Labor!$H$9 -> 2942.4546 | Q7: =$O7+$P7 -> 3160.2546 | R7: =MAX(0,$Q7-FARMER_HOURS) -> 2440.2546 | S7: =MIN($Q7,FARMER_HOURS)*FARMER_WAGE+IF(LABOR_MODE=1,$R7,ROUNDUP($R7/TEMP_HOURS_PER_WORKER,0)*TEMP_HOURS_PER_WORKER)*TEMP_WAGE -> 67361.22 | T7: =IF($N7=0,"",$S7-$S6) -> 2062.368 | U7: =IF($N7=0,"",$T7+FERT_TOMATO) -> 2942.368 | V7: =IF($N7=0,"",PRICE_TOMATO-$U7) -> 5857.632
A8: 3 | B8: {=INDEX(Labor!$B$5:$B$36,$A8+1)} -> 359.37 | C8: =MIN($B8,FARMER_HOURS) -> 359.37 | D8: =MAX(0,$B8-FARMER_HOURS) -> 0 | E8: =$C8*FARMER_WAGE+IF(LABOR_MODE=1,$D8,ROUNDUP($D8/TEMP_HOURS_PER_WORKER,0)*TEMP_HOURS_PER_WORKER)*TEMP_WAGE -> 12477.326 | F8: =IF($B8=0,0,$E8/$B8) -> 34.72 | G8: =$A8*FERT_TOMATO -> 2640 | H8: =$A8*PRICE_TOMATO -> 26400 | I8: =IF($A8=0,"",$E8-$E7) -> 4915.3104 | J8: =IF($A8=0,"",$I8+FERT_TOMATO) -> 5795.3104 | K8: =IF($A8=0,"",PRICE_TOMATO-$J8) -> 3004.6896 | L8: =$H8-$E8-$G8-FIXED_COST -> -8717.3264 | N8: 3 | O8: =$N8*HRS_PER_BED_TOMATO*WEEKS*(1+DIM_PCT_TOMATO)^$N8 -> 359.37 | P8: =Labor!$H$8+Labor!$H$9 -> 2942.4546 | Q8: =$O8+$P8 -> 3301.8246 | R8: =MAX(0,$Q8-FARMER_HOURS) -> 2581.8246 | S8: =MIN($Q8,FARMER_HOURS)*FARMER_WAGE+IF(LABOR_MODE=1,$R8,ROUNDUP($R8/TEMP_HOURS_PER_WORKER,0)*TEMP_HOURS_PER_WORKER)*TEMP_WAGE -> 69818.876 | T8: =IF($N8=0,"",$S8-$S7) -> 2457.6552 | U8: =IF($N8=0,"",$T8+FERT_TOMATO) -> 3337.6552 | V8: =IF($N8=0,"",PRICE_TOMATO-$U8) -> 5462.3448
A9: 4 | B9: {=INDEX(Labor!$B$5:$B$36,$A9+1)} -> 527.076 | C9: =MIN($B9,FARMER_HOURS) -> 527.076 | D9: =MAX(0,$B9-FARMER_HOURS) -> 0 | E9: =$C9*FARMER_WAGE+IF(LABOR_MODE=1,$D9,ROUNDUP($D9/TEMP_HOURS_PER_WORKER,0)*TEMP_HOURS_PER_WORKER)*TEMP_WAGE -> 18300.079 | F9: =IF($B9=0,0,$E9/$B9) -> 34.72 | G9: =$A9*FERT_TOMATO -> 3520 | H9: =$A9*PRICE_TOMATO -> 35200 | I9: =IF($A9=0,"",$E9-$E8) -> 5822.7523 | J9: =IF($A9=0,"",$I9+FERT_TOMATO) -> 6702.7523 | K9: =IF($A9=0,"",PRICE_TOMATO-$J9) -> 2097.2477 | L9: =$H9-$E9-$G9-FIXED_COST -> -6620.0787 | N9: 4 | O9: =$N9*HRS_PER_BED_TOMATO*WEEKS*(1+DIM_PCT_TOMATO)^$N9 -> 527.076 | P9: =Labor!$H$8+Labor!$H$9 -> 2942.4546 | Q9: =$O9+$P9 -> 3469.5306 | R9: =MAX(0,$Q9-FARMER_HOURS) -> 2749.5306 | S9: =MIN($Q9,FARMER_HOURS)*FARMER_WAGE+IF(LABOR_MODE=1,$R9,ROUNDUP($R9/TEMP_HOURS_PER_WORKER,0)*TEMP_HOURS_PER_WORKER)*TEMP_WAGE -> 72730.252 | T9: =IF($N9=0,"",$S9-$S8) -> 2911.3762 | U9: =IF($N9=0,"",$T9+FERT_TOMATO) -> 3791.3762 | V9: =IF($N9=0,"",PRICE_TOMATO-$U9) -> 5008.6238
A10: 5 | B10: {=INDEX(Labor!$B$5:$B$36,$A10+1)} -> 724.7295 | C10: =MIN($B10,FARMER_HOURS) -> 720 | D10: =MAX(0,$B10-FARMER_HOURS) -> 4.7295 | E10: =$C10*FARMER_WAGE+IF(LABOR_MODE=1,$D10,ROUNDUP($D10/TEMP_HOURS_PER_WORKER,0)*TEMP_HOURS_PER_WORKER)*TEMP_WAGE -> 25080.504 | F10: =IF($B10=0,0,$E10/$B10) -> 34.606711 | G10: =$A10*FERT_TOMATO -> 4400 | H10: =$A10*PRICE_TOMATO -> 44000 | I10: =IF($A10=0,"",$E10-$E9) -> 6780.4254 | J10: =IF($A10=0,"",$I10+FERT_TOMATO) -> 7660.4254 | K10: =IF($A10=0,"",PRICE_TOMATO-$J10) -> 1139.5746 | L10: =$H10-$E10-$G10-FIXED_COST -> -5480.5041 | N10: 5 | O10: =$N10*HRS_PER_BED_TOMATO*WEEKS*(1+DIM_PCT_TOMATO)^$N10 -> 724.7295 | P10: =Labor!$H$8+Labor!$H$9 -> 2942.4546 | Q10: =$O10+$P10 -> 3667.1841 | R10: =MAX(0,$Q10-FARMER_HOURS) -> 2947.1841 | S10: =MIN($Q10,FARMER_HOURS)*FARMER_WAGE+IF(LABOR_MODE=1,$R10,ROUNDUP($R10/TEMP_HOURS_PER_WORKER,0)*TEMP_HOURS_PER_WORKER)*TEMP_WAGE -> 76161.517 | T10: =IF($N10=0,"",$S10-$S9) -> 3431.2648 | U10: =IF($N10=0,"",$T10+FERT_TOMATO) -> 4311.2648 | V10: =IF($N10=0,"",PRICE_TOMATO-$U10) -> 4488.7352
A11: 6 | B11: {=INDEX(Labor!$B$5:$B$36,$A11+1)} -> 956.64294 | C11: =MIN($B11,FARMER_HOURS) -> 720 | D11: =MAX(0,$B11-FARMER_HOURS) -> 236.64294 | E11: =$C11*FARMER_WAGE+IF(LABOR_MODE=1,$D11,ROUNDUP($D11/TEMP_HOURS_PER_WORKER,0)*TEMP_HOURS_PER_WORKER)*TEMP_WAGE -> 29106.521 | F11: =IF($B11=0,0,$E11/$B11) -> 30.42569 | G11: =$A11*FERT_TOMATO -> 5280 | H11: =$A11*PRICE_TOMATO -> 52800 | I11: =IF($A11=0,"",$E11-$E10) -> 4026.0173 | J11: =IF($A11=0,"",$I11+FERT_TOMATO) -> 4906.0173 | K11: =IF($A11=0,"",PRICE_TOMATO-$J11) -> 3893.9827 | L11: =$H11-$E11-$G11-FIXED_COST -> -1586.5214 | N11: 6 | O11: =$N11*HRS_PER_BED_TOMATO*WEEKS*(1+DIM_PCT_TOMATO)^$N11 -> 956.64294 | P11: =Labor!$H$8+Labor!$H$9 -> 2942.4546 | Q11: =$O11+$P11 -> 3899.0976 | R11: =MAX(0,$Q11-FARMER_HOURS) -> 3179.0976 | S11: =MIN($Q11,FARMER_HOURS)*FARMER_WAGE+IF(LABOR_MODE=1,$R11,ROUNDUP($R11/TEMP_HOURS_PER_WORKER,0)*TEMP_HOURS_PER_WORKER)*TEMP_WAGE -> 80187.534 | T11: =IF($N11=0,"",$S11-$S10) -> 4026.0173 | U11: =IF($N11=0,"",$T11+FERT_TOMATO) -> 4906.0173 | V11: =IF($N11=0,"",PRICE_TOMATO-$U11) -> 3893.9827
A12: 7 | B12: {=INDEX(Labor!$B$5:$B$36,$A12+1)} -> 1227.6918 | C12: =MIN($B12,FARMER_HOURS) -> 720 | D12: =MAX(0,$B12-FARMER_HOURS) -> 507.69177 | E12: =$C12*FARMER_WAGE+IF(LABOR_MODE=1,$D12,ROUNDUP($D12/TEMP_HOURS_PER_WORKER,0)*TEMP_HOURS_PER_WORKER)*TEMP_WAGE -> 33811.929 | F12: =IF($B12=0,0,$E12/$B12) -> 27.541057 | G12: =$A12*FERT_TOMATO -> 6160 | H12: =$A12*PRICE_TOMATO -> 61600 | I12: =IF($A12=0,"",$E12-$E11) -> 4705.4077 | J12: =IF($A12=0,"",$I12+FERT_TOMATO) -> 5585.4077 | K12: =IF($A12=0,"",PRICE_TOMATO-$J12) -> 3214.5923 | L12: =$H12-$E12-$G12-FIXED_COST -> 1628.0708 | N12: 7 | O12: =$N12*HRS_PER_BED_TOMATO*WEEKS*(1+DIM_PCT_TOMATO)^$N12 -> 1227.6918 | P12: =Labor!$H$8+Labor!$H$9 -> 2942.4546 | Q12: =$O12+$P12 -> 4170.1464 | R12: =MAX(0,$Q12-FARMER_HOURS) -> 3450.1464 | S12: =MIN($Q12,FARMER_HOURS)*FARMER_WAGE+IF(LABOR_MODE=1,$R12,ROUNDUP($R12/TEMP_HOURS_PER_WORKER,0)*TEMP_HOURS_PER_WORKER)*TEMP_WAGE -> 84892.942 | T12: =IF($N12=0,"",$S12-$S11) -> 4705.4077 | U12: =IF($N12=0,"",$T12+FERT_TOMATO) -> 5585.4077 | V12: =IF($N12=0,"",PRICE_TOMATO-$U12) -> 3214.5923
A13: 8 | B13: {=INDEX(Labor!$B$5:$B$36,$A13+1)} -> 1543.3839 | C13: =MIN($B13,FARMER_HOURS) -> 720 | D13: =MAX(0,$B13-FARMER_HOURS) -> 823.38394 | E13: =$C13*FARMER_WAGE+IF(LABOR_MODE=1,$D13,ROUNDUP($D13/TEMP_HOURS_PER_WORKER,0)*TEMP_HOURS_PER_WORKER)*TEMP_WAGE -> 39292.345 | F13: =IF($B13=0,0,$E13/$B13) -> 25.458568 | G13: =$A13*FERT_TOMATO -> 7040 | H13: =$A13*PRICE_TOMATO -> 70400 | I13: =IF($A13=0,"",$E13-$E12) -> 5480.4161 | J13: =IF($A13=0,"",$I13+FERT_TOMATO) -> 6360.4161 | K13: =IF($A13=0,"",PRICE_TOMATO-$J13) -> 2439.5839 | L13: =$H13-$E13-$G13-FIXED_COST -> 4067.6547 | N13: 8 | O13: =$N13*HRS_PER_BED_TOMATO*WEEKS*(1+DIM_PCT_TOMATO)^$N13 -> 1543.3839 | P13: =Labor!$H$8+Labor!$H$9 -> 2942.4546 | Q13: =$O13+$P13 -> 4485.8386 | R13: =MAX(0,$Q13-FARMER_HOURS) -> 3765.8386 | S13: =MIN($Q13,FARMER_HOURS)*FARMER_WAGE+IF(LABOR_MODE=1,$R13,ROUNDUP($R13/TEMP_HOURS_PER_WORKER,0)*TEMP_HOURS_PER_WORKER)*TEMP_WAGE -> 90373.358 | T13: =IF($N13=0,"",$S13-$S12) -> 5480.4161 | U13: =IF($N13=0,"",$T13+FERT_TOMATO) -> 6360.4161 | V13: =IF($N13=0,"",PRICE_TOMATO-$U13) -> 2439.5839
A14: 9 | B14: {=INDEX(Labor!$B$5:$B$36,$A14+1)} -> 1909.9376 | C14: =MIN($B14,FARMER_HOURS) -> 720 | D14: =MAX(0,$B14-FARMER_HOURS) -> 1189.9376 | E14: =$C14*FARMER_WAGE+IF(LABOR_MODE=1,$D14,ROUNDUP($D14/TEMP_HOURS_PER_WORKER,0)*TEMP_HOURS_PER_WORKER)*TEMP_WAGE -> 45655.717 | F14: =IF($B14=0,0,$E14/$B14) -> 23.904297 | G14: =$A14*FERT_TOMATO -> 7920 | H14: =$A14*PRICE_TOMATO -> 79200 | I14: =IF($A14=0,"",$E14-$E13) -> 6363.372 | J14: =IF($A14=0,"",$I14+FERT_TOMATO) -> 7243.372 | K14: =IF($A14=0,"",PRICE_TOMATO-$J14) -> 1556.628 | L14: =$H14-$E14-$G14-FIXED_COST -> 5624.2827 | N14: 9 | O14: =$N14*HRS_PER_BED_TOMATO*WEEKS*(1+DIM_PCT_TOMATO)^$N14 -> 1909.9376 | P14: =Labor!$H$8+Labor!$H$9 -> 2942.4546 | Q14: =$O14+$P14 -> 4852.3923 | R14: =MAX(0,$Q14-FARMER_HOURS) -> 4132.3923 | S14: =MIN($Q14,FARMER_HOURS)*FARMER_WAGE+IF(LABOR_MODE=1,$R14,ROUNDUP($R14/TEMP_HOURS_PER_WORKER,0)*TEMP_HOURS_PER_WORKER)*TEMP_WAGE -> 96736.73 | T14: =IF($N14=0,"",$S14-$S13) -> 6363.372 | U14: =IF($N14=0,"",$T14+FERT_TOMATO) -> 7243.372 | V14: =IF($N14=0,"",PRICE_TOMATO-$U14) -> 1556.628
A15: 10 | B15: {=INDEX(Labor!$B$5:$B$36,$A15+1)} -> 2334.3682 | C15: =MIN($B15,FARMER_HOURS) -> 720 | D15: =MAX(0,$B15-FARMER_HOURS) -> 1614.3682 | E15: =$C15*FARMER_WAGE+IF(LABOR_MODE=1,$D15,ROUNDUP($D15/TEMP_HOURS_PER_WORKER,0)*TEMP_HOURS_PER_WORKER)*TEMP_WAGE -> 53023.832 | F15: =IF($B15=0,0,$E15/$B15) -> 22.714425 | G15: =$A15*FERT_TOMATO -> 8800 | H15: =$A15*PRICE_TOMATO -> 88000 | I15: =IF($A15=0,"",$E15-$E14) -> 7368.1149 | J15: =IF($A15=0,"",$I15+FERT_TOMATO) -> 8248.1149 | K15: =IF($A15=0,"",PRICE_TOMATO-$J15) -> 551.88506 | L15: =$H15-$E15-$G15-FIXED_COST -> 6176.1678 | N15: 10 | O15: =$N15*HRS_PER_BED_TOMATO*WEEKS*(1+DIM_PCT_TOMATO)^$N15 -> 2334.3682 | P15: =Labor!$H$8+Labor!$H$9 -> 2942.4546 | Q15: =$O15+$P15 -> 5276.8228 | R15: =MAX(0,$Q15-FARMER_HOURS) -> 4556.8228 | S15: =MIN($Q15,FARMER_HOURS)*FARMER_WAGE+IF(LABOR_MODE=1,$R15,ROUNDUP($R15/TEMP_HOURS_PER_WORKER,0)*TEMP_HOURS_PER_WORKER)*TEMP_WAGE -> 104104.84 | T15: =IF($N15=0,"",$S15-$S14) -> 7368.1149 | U15: =IF($N15=0,"",$T15+FERT_TOMATO) -> 8248.1149 | V15: =IF($N15=0,"",PRICE_TOMATO-$U15) -> 551.88506
A16: 11 | B16: {=INDEX(Labor!$B$5:$B$36,$A16+1)} -> 2824.5855 | C16: =MIN($B16,FARMER_HOURS) -> 720 | D16: =MAX(0,$B16-FARMER_HOURS) -> 2104.5855 | E16: =$C16*FARMER_WAGE+IF(LABOR_MODE=1,$D16,ROUNDUP($D16/TEMP_HOURS_PER_WORKER,0)*TEMP_HOURS_PER_WORKER)*TEMP_WAGE -> 61534.005 | F16: =IF($B16=0,0,$E16/$B16) -> 21.785145 | G16: =$A16*FERT_TOMATO -> 9680 | H16: =$A16*PRICE_TOMATO -> 96800 | I16: =IF($A16=0,"",$E16-$E15) -> 8510.1728 | J16: =IF($A16=0,"",$I16+FERT_TOMATO) -> 9390.1728 | K16: =IF($A16=0,"",PRICE_TOMATO-$J16) -> -590.17276 | L16: =$H16-$E16-$G16-FIXED_COST -> 5585.995 | N16: 11 | O16: =$N16*HRS_PER_BED_TOMATO*WEEKS*(1+DIM_PCT_TOMATO)^$N16 -> 2824.5855 | P16: =Labor!$H$8+Labor!$H$9 -> 2942.4546 | Q16: =$O16+$P16 -> 5767.0402 | R16: =MAX(0,$Q16-FARMER_HOURS) -> 5047.0402 | S16: =MIN($Q16,FARMER_HOURS)*FARMER_WAGE+IF(LABOR_MODE=1,$R16,ROUNDUP($R16/TEMP_HOURS_PER_WORKER,0)*TEMP_HOURS_PER_WORKER)*TEMP_WAGE -> 112615.02 | T16: =IF($N16=0,"",$S16-$S15) -> 8510.1728 | U16: =IF($N16=0,"",$T16+FERT_TOMATO) -> 9390.1728 | V16: =IF($N16=0,"",PRICE_TOMATO-$U16) -> -590.17276
... A25: 20 | B25: {=INDEX(Labor!$B$5:$B$36,$A25+1)} -> 12109.5 | C25: =MIN($B25,FARMER_HOURS) -> 720 | D25: =MAX(0,$B25-FARMER_HOURS) -> 11389.5 | E25: =$C25*FARMER_WAGE+IF(LABOR_MODE=1,$D25,ROUNDUP($D25/TEMP_HOURS_PER_WORKER,0)*TEMP_HOURS_PER_WORKER)*TEMP_WAGE -> 222720.12 | F25: =IF($B25=0,0,$E25/$B25) -> 18.392181 | G25: =$A25*FERT_TOMATO -> 17600 | H25: =$A25*PRICE_TOMATO -> 176000 | I25: =IF($A25=0,"",$E25-$E24) -> 28666.489 | J25: =IF($A25=0,"",$I25+FERT_TOMATO) -> 29546.489 | K25: =IF($A25=0,"",PRICE_TOMATO-$J25) -> -20746.489 | L25: =$H25-$E25-$G25-FIXED_COST -> -84320.118 | N25: 20 | O25: =$N25*HRS_PER_BED_TOMATO*WEEKS*(1+DIM_PCT_TOMATO)^$N25 -> 12109.5 | P25: =Labor!$H$8+Labor!$H$9 -> 2942.4546 | Q25: =$O25+$P25 -> 15051.955 | R25: =MAX(0,$Q25-FARMER_HOURS) -> 14331.955 | S25: =MIN($Q25,FARMER_HOURS)*FARMER_WAGE+IF(LABOR_MODE=1,$R25,ROUNDUP($R25/TEMP_HOURS_PER_WORKER,0)*TEMP_HOURS_PER_WORKER)*TEMP_WAGE -> 273801.13 | T25: =IF($N25=0,"",$S25-$S24) -> 28666.489 | U25: =IF($N25=0,"",$T25+FERT_TOMATO) -> 29546.489 | V25: =IF($N25=0,"",PRICE_TOMATO-$U25) -> -20746.489
N26: 21 | O26: =$N26*HRS_PER_BED_TOMATO*WEEKS*(1+DIM_PCT_TOMATO)^$N26 -> 13986.472 | P26: =Labor!$H$8+Labor!$H$9 -> 2942.4546 | Q26: =$O26+$P26 -> 16928.927 | R26: =MAX(0,$Q26-FARMER_HOURS) -> 16208.927 | S26: =MIN($Q26,FARMER_HOURS)*FARMER_WAGE+IF(LABOR_MODE=1,$R26,ROUNDUP($R26/TEMP_HOURS_PER_WORKER,0)*TEMP_HOURS_PER_WORKER)*TEMP_WAGE -> 306385.37 | T26: =IF($N26=0,"",$S26-$S25) -> 32584.242 | U26: =IF($N26=0,"",$T26+FERT_TOMATO) -> 33464.242 | V26: =IF($N26=0,"",PRICE_TOMATO-$U26) -> -24664.242
A27: Carrots — standalone | N27: Carrots — at the optimum
A28: q (beds) | B28: Labor hrs | C28: Farmer hrs | D28: Temp hrs | E28: Labor $ | F28: Blended $/hr | G28: Fertilizer $ | H28: Revenue $ | I28: MC labor $/bed | J28: MC total $/bed | K28: Price − MC | L28: Standalone profit | N28: q (beds) | O28: This crop hrs | P28: Other crops hrs | Q28: Total farm hrs | R28: Temp hrs | S28: Total farm labor $ | T28: MC labor $/bed | U28: MC total $/bed | V28: Price − MC
A29: 0 | B29: {=INDEX(Labor!$C$5:$C$36,$A29+1)} -> 0 | C29: =MIN($B29,FARMER_HOURS) -> 0 | D29: =MAX(0,$B29-FARMER_HOURS) -> 0 | E29: =$C29*FARMER_WAGE+IF(LABOR_MODE=1,$D29,ROUNDUP($D29/TEMP_HOURS_PER_WORKER,0)*TEMP_HOURS_PER_WORKER)*TEMP_WAGE -> 0 | F29: =IF($B29=0,0,$E29/$B29) -> 0 | G29: =$A29*FERT_CARROT -> 0 | H29: =$A29*PRICE_CARROT -> 0 | I29: =IF($A29=0,"",$E29-$E28) | J29: =IF($A29=0,"",$I29+FERT_CARROT) | K29: =IF($A29=0,"",PRICE_CARROT-$J29) | L29: =$H29-$E29-$G29-FIXED_COST -> -20000 | N29: 0 | O29: =$N29*HRS_PER_BED_CARROT*WEEKS*(1+DIM_PCT_CARROT)^$N29 -> 0 | P29: =Labor!$H$7+Labor!$H$9 -> 4294.0463 | Q29: =$O29+$P29 -> 4294.0463 | R29: =MAX(0,$Q29-FARMER_HOURS) -> 3574.0463 | S29: =MIN($Q29,FARMER_HOURS)*FARMER_WAGE+IF(LABOR_MODE=1,$R29,ROUNDUP($R29/TEMP_HOURS_PER_WORKER,0)*TEMP_HOURS_PER_WORKER)*TEMP_WAGE -> 87043.843 | T29: =IF($N29=0,"",$S29-$S28) | U29: =IF($N29=0,"",$T29+FERT_CARROT) | V29: =IF($N29=0,"",PRICE_CARROT-$U29)
A30: 1 | B30: {=INDEX(Labor!$C$5:$C$36,$A30+1)} -> 30.7377 | C30: =MIN($B30,FARMER_HOURS) -> 30.7377 | D30: =MAX(0,$B30-FARMER_HOURS) -> 0 | E30: =$C30*FARMER_WAGE+IF(LABOR_MODE=1,$D30,ROUNDUP($D30/TEMP_HOURS_PER_WORKER,0)*TEMP_HOURS_PER_WORKER)*TEMP_WAGE -> 1067.2129 | F30: =IF($B30=0,0,$E30/$B30) -> 34.72 | G30: =$A30*FERT_CARROT -> 440 | H30: =$A30*PRICE_CARROT -> 2094 | I30: =IF($A30=0,"",$E30-$E29) -> 1067.2129 | J30: =IF($A30=0,"",$I30+FERT_CARROT) -> 1507.2129 | K30: =IF($A30=0,"",PRICE_CARROT-$J30) -> 586.78706 | L30: =$H30-$E30-$G30-FIXED_COST -> -19413.213 | N30: 1 | O30: =$N30*HRS_PER_BED_CARROT*WEEKS*(1+DIM_PCT_CARROT)^$N30 -> 30.7377 | P30: =Labor!$H$7+Labor!$H$9 -> 4294.0463 | Q30: =$O30+$P30 -> 4324.784 | R30: =MAX(0,$Q30-FARMER_HOURS) -> 3604.784 | S30: =MIN($Q30,FARMER_HOURS)*FARMER_WAGE+IF(LABOR_MODE=1,$R30,ROUNDUP($R30/TEMP_HOURS_PER_WORKER,0)*TEMP_HOURS_PER_WORKER)*TEMP_WAGE -> 87577.449 | T30: =IF($N30=0,"",$S30-$S29) -> 533.60647 | U30: =IF($N30=0,"",$T30+FERT_CARROT) -> 973.60647 | V30: =IF($N30=0,"",PRICE_CARROT-$U30) -> 1120.3935
A31: 2 | B31: {=INDEX(Labor!$C$5:$C$36,$A31+1)} -> 63.012285 | C31: =MIN($B31,FARMER_HOURS) -> 63.012285 | D31: =MAX(0,$B31-FARMER_HOURS) -> 0 | E31: =$C31*FARMER_WAGE+IF(LABOR_MODE=1,$D31,ROUNDUP($D31/TEMP_HOURS_PER_WORKER,0)*TEMP_HOURS_PER_WORKER)*TEMP_WAGE -> 2187.7865 | F31: =IF($B31=0,0,$E31/$B31) -> 34.72 | G31: =$A31*FERT_CARROT -> 880 | H31: =$A31*PRICE_CARROT -> 4188 | I31: =IF($A31=0,"",$E31-$E30) -> 1120.5736 | J31: =IF($A31=0,"",$I31+FERT_CARROT) -> 1560.5736 | K31: =IF($A31=0,"",PRICE_CARROT-$J31) -> 533.42641 | L31: =$H31-$E31-$G31-FIXED_COST -> -18879.787 | N31: 2 | O31: =$N31*HRS_PER_BED_CARROT*WEEKS*(1+DIM_PCT_CARROT)^$N31 -> 63.012285 | P31: =Labor!$H$7+Labor!$H$9 -> 4294.0463 | Q31: =$O31+$P31 -> 4357.0585 | R31: =MAX(0,$Q31-FARMER_HOURS) -> 3637.0585 | S31: =MIN($Q31,FARMER_HOURS)*FARMER_WAGE+IF(LABOR_MODE=1,$R31,ROUNDUP($R31/TEMP_HOURS_PER_WORKER,0)*TEMP_HOURS_PER_WORKER)*TEMP_WAGE -> 88137.736 | T31: =IF($N31=0,"",$S31-$S30) -> 560.2868 | U31: =IF($N31=0,"",$T31+FERT_CARROT) -> 1000.2868 | V31: =IF($N31=0,"",PRICE_CARROT-$U31) -> 1093.7132
A32: 3 | B32: {=INDEX(Labor!$C$5:$C$36,$A32+1)} -> 96.881388 | C32: =MIN($B32,FARMER_HOURS) -> 96.881388 | D32: =MAX(0,$B32-FARMER_HOURS) -> 0 | E32: =$C32*FARMER_WAGE+IF(LABOR_MODE=1,$D32,ROUNDUP($D32/TEMP_HOURS_PER_WORKER,0)*TEMP_HOURS_PER_WORKER)*TEMP_WAGE -> 3363.7218 | F32: =IF($B32=0,0,$E32/$B32) -> 34.72 | G32: =$A32*FERT_CARROT -> 1320 | H32: =$A32*PRICE_CARROT -> 6282 | I32: =IF($A32=0,"",$E32-$E31) -> 1175.9353 | J32: =IF($A32=0,"",$I32+FERT_CARROT) -> 1615.9353 | K32: =IF($A32=0,"",PRICE_CARROT-$J32) -> 478.06474 | L32: =$H32-$E32-$G32-FIXED_COST -> -18401.722 | N32: 3 | O32: =$N32*HRS_PER_BED_CARROT*WEEKS*(1+DIM_PCT_CARROT)^$N32 -> 96.881388 | P32: =Labor!$H$7+Labor!$H$9 -> 4294.0463 | Q32: =$O32+$P32 -> 4390.9276 | R32: =MAX(0,$Q32-FARMER_HOURS) -> 3670.9276 | S32: =MIN($Q32,FARMER_HOURS)*FARMER_WAGE+IF(LABOR_MODE=1,$R32,ROUNDUP($R32/TEMP_HOURS_PER_WORKER,0)*TEMP_HOURS_PER_WORKER)*TEMP_WAGE -> 88725.704 | T32: =IF($N32=0,"",$S32-$S31) -> 587.96763 | U32: =IF($N32=0,"",$T32+FERT_CARROT) -> 1027.9676 | V32: =IF($N32=0,"",PRICE_CARROT-$U32) -> 1066.0324
A33: 4 | B33: {=INDEX(Labor!$C$5:$C$36,$A33+1)} -> 132.40456 | C33: =MIN($B33,FARMER_HOURS) -> 132.40456 | D33: =MAX(0,$B33-FARMER_HOURS) -> 0 | E33: =$C33*FARMER_WAGE+IF(LABOR_MODE=1,$D33,ROUNDUP($D33/TEMP_HOURS_PER_WORKER,0)*TEMP_HOURS_PER_WORKER)*TEMP_WAGE -> 4597.0865 | F33: =IF($B33=0,0,$E33/$B33) -> 34.72 | G33: =$A33*FERT_CARROT -> 1760 | H33: =$A33*PRICE_CARROT -> 8376 | I33: =IF($A33=0,"",$E33-$E32) -> 1233.3647 | J33: =IF($A33=0,"",$I33+FERT_CARROT) -> 1673.3647 | K33: =IF($A33=0,"",PRICE_CARROT-$J33) -> 420.63534 | L33: =$H33-$E33-$G33-FIXED_COST -> -17981.086 | N33: 4 | O33: =$N33*HRS_PER_BED_CARROT*WEEKS*(1+DIM_PCT_CARROT)^$N33 -> 132.40456 | P33: =Labor!$H$7+Labor!$H$9 -> 4294.0463 | Q33: =$O33+$P33 -> 4426.4508 | R33: =MAX(0,$Q33-FARMER_HOURS) -> 3706.4508 | S33: =MIN($Q33,FARMER_HOURS)*FARMER_WAGE+IF(LABOR_MODE=1,$R33,ROUNDUP($R33/TEMP_HOURS_PER_WORKER,0)*TEMP_HOURS_PER_WORKER)*TEMP_WAGE -> 89342.386 | T33: =IF($N33=0,"",$S33-$S32) -> 616.68233 | U33: =IF($N33=0,"",$T33+FERT_CARROT) -> 1056.6823 | V33: =IF($N33=0,"",PRICE_CARROT-$U33) -> 1037.3177
A34: 5 | B34: {=INDEX(Labor!$C$5:$C$36,$A34+1)} -> 169.64335 | C34: =MIN($B34,FARMER_HOURS) -> 169.64335 | D34: =MAX(0,$B34-FARMER_HOURS) -> 0 | E34: =$C34*FARMER_WAGE+IF(LABOR_MODE=1,$D34,ROUNDUP($D34/TEMP_HOURS_PER_WORKER,0)*TEMP_HOURS_PER_WORKER)*TEMP_WAGE -> 5890.017 | F34: =IF($B34=0,0,$E34/$B34) -> 34.72 | G34: =$A34*FERT_CARROT -> 2200 | H34: =$A34*PRICE_CARROT -> 10470 | I34: =IF($A34=0,"",$E34-$E33) -> 1292.9306 | J34: =IF($A34=0,"",$I34+FERT_CARROT) -> 1732.9306 | K34: =IF($A34=0,"",PRICE_CARROT-$J34) -> 361.06943 | L34: =$H34-$E34-$G34-FIXED_COST -> -17620.017 | N34: 5 | O34: =$N34*HRS_PER_BED_CARROT*WEEKS*(1+DIM_PCT_CARROT)^$N34 -> 169.64335 | P34: =Labor!$H$7+Labor!$H$9 -> 4294.0463 | Q34: =$O34+$P34 -> 4463.6896 | R34: =MAX(0,$Q34-FARMER_HOURS) -> 3743.6896 | S34: =MIN($Q34,FARMER_HOURS)*FARMER_WAGE+IF(LABOR_MODE=1,$R34,ROUNDUP($R34/TEMP_HOURS_PER_WORKER,0)*TEMP_HOURS_PER_WORKER)*TEMP_WAGE -> 89988.851 | T34: =IF($N34=0,"",$S34-$S33) -> 646.46528 | U34: =IF($N34=0,"",$T34+FERT_CARROT) -> 1086.4653 | V34: =IF($N34=0,"",PRICE_CARROT-$U34) -> 1007.5347
A35: 6 | B35: {=INDEX(Labor!$C$5:$C$36,$A35+1)} -> 208.66132 | C35: =MIN($B35,FARMER_HOURS) -> 208.66132 | D35: =MAX(0,$B35-FARMER_HOURS) -> 0 | E35: =$C35*FARMER_WAGE+IF(LABOR_MODE=1,$D35,ROUNDUP($D35/TEMP_HOURS_PER_WORKER,0)*TEMP_HOURS_PER_WORKER)*TEMP_WAGE -> 7244.7209 | F35: =IF($B35=0,0,$E35/$B35) -> 34.72 | G35: =$A35*FERT_CARROT -> 2640 | H35: =$A35*PRICE_CARROT -> 12564 | I35: =IF($A35=0,"",$E35-$E34) -> 1354.7039 | J35: =IF($A35=0,"",$I35+FERT_CARROT) -> 1794.7039 | K35: =IF($A35=0,"",PRICE_CARROT-$J35) -> 299.29608 | L35: =$H35-$E35-$G35-FIXED_COST -> -17320.721 | N35: 6 | O35: =$N35*HRS_PER_BED_CARROT*WEEKS*(1+DIM_PCT_CARROT)^$N35 -> 208.66132 | P35: =Labor!$H$7+Labor!$H$9 -> 4294.0463 | Q35: =$O35+$P35 -> 4502.7076 | R35: =MAX(0,$Q35-FARMER_HOURS) -> 3782.7076 | S35: =MIN($Q35,FARMER_HOURS)*FARMER_WAGE+IF(LABOR_MODE=1,$R35,ROUNDUP($R35/TEMP_HOURS_PER_WORKER,0)*TEMP_HOURS_PER_WORKER)*TEMP_WAGE -> 90666.203 | T35: =IF($N35=0,"",$S35-$S34) -> 677.35196 | U35: =IF($N35=0,"",$T35+FERT_CARROT) -> 1117.352 | V35: =IF($N35=0,"",PRICE_CARROT-$U35) -> 976.64804
A36: 7 | B36: {=INDEX(Labor!$C$5:$C$36,$A36+1)} -> 249.52416 | C36: =MIN($B36,FARMER_HOURS) -> 249.52416 | D36: =MAX(0,$B36-FARMER_HOURS) -> 0 | E36: =$C36*FARMER_WAGE+IF(LABOR_MODE=1,$D36,ROUNDUP($D36/TEMP_HOURS_PER_WORKER,0)*TEMP_HOURS_PER_WORKER)*TEMP_WAGE -> 8663.4788 | F36: =IF($B36=0,0,$E36/$B36) -> 34.72 | G36: =$A36*FERT_CARROT -> 3080 | H36: =$A36*PRICE_CARROT -> 14658 | I36: =IF($A36=0,"",$E36-$E35) -> 1418.7579 | J36: =IF($A36=0,"",$I36+FERT_CARROT) -> 1858.7579 | K36: =IF($A36=0,"",PRICE_CARROT-$J36) -> 235.24215 | L36: =$H36-$E36-$G36-FIXED_COST -> -17085.479 | N36: 7 | O36: =$N36*HRS_PER_BED_CARROT*WEEKS*(1+DIM_PCT_CARROT)^$N36 -> 249.52416 | P36: =Labor!$H$7+Labor!$H$9 -> 4294.0463 | Q36: =$O36+$P36 -> 4543.5704 | R36: =MAX(0,$Q36-FARMER_HOURS) -> 3823.5704 | S36: =MIN($Q36,FARMER_HOURS)*FARMER_WAGE+IF(LABOR_MODE=1,$R36,ROUNDUP($R36/TEMP_HOURS_PER_WORKER,0)*TEMP_HOURS_PER_WORKER)*TEMP_WAGE -> 91375.582 | T36: =IF($N36=0,"",$S36-$S35) -> 709.37893 | U36: =IF($N36=0,"",$T36+FERT_CARROT) -> 1149.3789 | V36: =IF($N36=0,"",PRICE_CARROT-$U36) -> 944.62107
A37: 8 | B37: {=INDEX(Labor!$C$5:$C$36,$A37+1)} -> 292.29973 | C37: =MIN($B37,FARMER_HOURS) -> 292.29973 | D37: =MAX(0,$B37-FARMER_HOURS) -> 0 | E37: =$C37*FARMER_WAGE+IF(LABOR_MODE=1,$D37,ROUNDUP($D37/TEMP_HOURS_PER_WORKER,0)*TEMP_HOURS_PER_WORKER)*TEMP_WAGE -> 10148.647 | F37: =IF($B37=0,0,$E37/$B37) -> 34.72 | G37: =$A37*FERT_CARROT -> 3520 | H37: =$A37*PRICE_CARROT -> 16752 | I37: =IF($A37=0,"",$E37-$E36) -> 1485.1678 | J37: =IF($A37=0,"",$I37+FERT_CARROT) -> 1925.1678 | K37: =IF($A37=0,"",PRICE_CARROT-$J37) -> 168.83221 | L37: =$H37-$E37-$G37-FIXED_COST -> -16916.647 | N37: 8 | O37: =$N37*HRS_PER_BED_CARROT*WEEKS*(1+DIM_PCT_CARROT)^$N37 -> 292.29973 | P37: =Labor!$H$7+Labor!$H$9 -> 4294.0463 | Q37: =$O37+$P37 -> 4586.346 | R37: =MAX(0,$Q37-FARMER_HOURS) -> 3866.346 | S37: =MIN($Q37,FARMER_HOURS)*FARMER_WAGE+IF(LABOR_MODE=1,$R37,ROUNDUP($R37/TEMP_HOURS_PER_WORKER,0)*TEMP_HOURS_PER_WORKER)*TEMP_WAGE -> 92118.166 | T37: =IF($N37=0,"",$S37-$S36) -> 742.5839 | U37: =IF($N37=0,"",$T37+FERT_CARROT) -> 1182.5839 | V37: =IF($N37=0,"",PRICE_CARROT-$U37) -> 911.4161
A38: 9 | B38: {=INDEX(Labor!$C$5:$C$36,$A38+1)} -> 337.05812 | C38: =MIN($B38,FARMER_HOURS) -> 337.05812 | D38: =MAX(0,$B38-FARMER_HOURS) -> 0 | E38: =$C38*FARMER_WAGE+IF(LABOR_MODE=1,$D38,ROUNDUP($D38/TEMP_HOURS_PER_WORKER,0)*TEMP_HOURS_PER_WORKER)*TEMP_WAGE -> 11702.658 | F38: =IF($B38=0,0,$E38/$B38) -> 34.72 | G38: =$A38*FERT_CARROT -> 3960 | H38: =$A38*PRICE_CARROT -> 18846 | I38: =IF($A38=0,"",$E38-$E37) -> 1554.0115 | J38: =IF($A38=0,"",$I38+FERT_CARROT) -> 1994.0115 | K38: =IF($A38=0,"",PRICE_CARROT-$J38) -> 99.988492 | L38: =$H38-$E38-$G38-FIXED_COST -> -16816.658 | N38: 9 | O38: =$N38*HRS_PER_BED_CARROT*WEEKS*(1+DIM_PCT_CARROT)^$N38 -> 337.05812 | P38: =Labor!$H$7+Labor!$H$9 -> 4294.0463 | Q38: =$O38+$P38 -> 4631.1044 | R38: =MAX(0,$Q38-FARMER_HOURS) -> 3911.1044 | S38: =MIN($Q38,FARMER_HOURS)*FARMER_WAGE+IF(LABOR_MODE=1,$R38,ROUNDUP($R38/TEMP_HOURS_PER_WORKER,0)*TEMP_HOURS_PER_WORKER)*TEMP_WAGE -> 92895.172 | T38: =IF($N38=0,"",$S38-$S37) -> 777.00575 | U38: =IF($N38=0,"",$T38+FERT_CARROT) -> 1217.0058 | V38: =IF($N38=0,"",PRICE_CARROT-$U38) -> 876.99425
A39: 10 | B39: {=INDEX(Labor!$C$5:$C$36,$A39+1)} -> 383.87175 | C39: =MIN($B39,FARMER_HOURS) -> 383.87175 | D39: =MAX(0,$B39-FARMER_HOURS) -> 0 | E39: =$C39*FARMER_WAGE+IF(LABOR_MODE=1,$D39,ROUNDUP($D39/TEMP_HOURS_PER_WORKER,0)*TEMP_HOURS_PER_WORKER)*TEMP_WAGE -> 13328.027 | F39: =IF($B39=0,0,$E39/$B39) -> 34.72 | G39: =$A39*FERT_CARROT -> 4400 | H39: =$A39*PRICE_CARROT -> 20940 | I39: =IF($A39=0,"",$E39-$E38) -> 1625.3692 | J39: =IF($A39=0,"",$I39+FERT_CARROT) -> 2065.3692 | K39: =IF($A39=0,"",PRICE_CARROT-$J39) -> 28.630821 | L39: =$H39-$E39-$G39-FIXED_COST -> -16788.027 | N39: 10 | O39: =$N39*HRS_PER_BED_CARROT*WEEKS*(1+DIM_PCT_CARROT)^$N39 -> 383.87175 | P39: =Labor!$H$7+Labor!$H$9 -> 4294.0463 | Q39: =$O39+$P39 -> 4677.918 | R39: =MAX(0,$Q39-FARMER_HOURS) -> 3957.918 | S39: =MIN($Q39,FARMER_HOURS)*FARMER_WAGE+IF(LABOR_MODE=1,$R39,ROUNDUP($R39/TEMP_HOURS_PER_WORKER,0)*TEMP_HOURS_PER_WORKER)*TEMP_WAGE -> 93707.857 | T39: =IF($N39=0,"",$S39-$S38) -> 812.68459 | U39: =IF($N39=0,"",$T39+FERT_CARROT) -> 1252.6846 | V39: =IF($N39=0,"",PRICE_CARROT-$U39) -> 841.31541
A40: 11 | B40: {=INDEX(Labor!$C$5:$C$36,$A40+1)} -> 432.8154 | C40: =MIN($B40,FARMER_HOURS) -> 432.8154 | D40: =MAX(0,$B40-FARMER_HOURS) -> 0 | E40: =$C40*FARMER_WAGE+IF(LABOR_MODE=1,$D40,ROUNDUP($D40/TEMP_HOURS_PER_WORKER,0)*TEMP_HOURS_PER_WORKER)*TEMP_WAGE -> 15027.351 | F40: =IF($B40=0,0,$E40/$B40) -> 34.72 | G40: =$A40*FERT_CARROT -> 4840 | H40: =$A40*PRICE_CARROT -> 23034 | I40: =IF($A40=0,"",$E40-$E39) -> 1699.3235 | J40: =IF($A40=0,"",$I40+FERT_CARROT) -> 2139.3235 | K40: =IF($A40=0,"",PRICE_CARROT-$J40) -> -45.323477 | L40: =$H40-$E40-$G40-FIXED_COST -> -16833.351 | N40: 11 | O40: =$N40*HRS_PER_BED_CARROT*WEEKS*(1+DIM_PCT_CARROT)^$N40 -> 432.8154 | P40: =Labor!$H$7+Labor!$H$9 -> 4294.0463 | Q40: =$O40+$P40 -> 4726.8617 | R40: =MAX(0,$Q40-FARMER_HOURS) -> 4006.8617 | S40: =MIN($Q40,FARMER_HOURS)*FARMER_WAGE+IF(LABOR_MODE=1,$R40,ROUNDUP($R40/TEMP_HOURS_PER_WORKER,0)*TEMP_HOURS_PER_WORKER)*TEMP_WAGE -> 94557.518 | T40: =IF($N40=0,"",$S40-$S39) -> 849.66174 | U40: =IF($N40=0,"",$T40+FERT_CARROT) -> 1289.6617 | V40: =IF($N40=0,"",PRICE_CARROT-$U40) -> 804.33826
... A49: 20 | B49: {=INDEX(Labor!$C$5:$C$36,$A49+1)} -> 982.7766 | C49: =MIN($B49,FARMER_HOURS) -> 720 | D49: =MAX(0,$B49-FARMER_HOURS) -> 262.7766 | E49: =$C49*FARMER_WAGE+IF(LABOR_MODE=1,$D49,ROUNDUP($D49/TEMP_HOURS_PER_WORKER,0)*TEMP_HOURS_PER_WORKER)*TEMP_WAGE -> 29560.202 | F49: =IF($B49=0,0,$E49/$B49) -> 30.078252 | G49: =$A49*FERT_CARROT -> 8800 | H49: =$A49*PRICE_CARROT -> 41880 | I49: =IF($A49=0,"",$E49-$E48) -> 1248.366 | J49: =IF($A49=0,"",$I49+FERT_CARROT) -> 1688.366 | K49: =IF($A49=0,"",PRICE_CARROT-$J49) -> 405.63402 | L49: =$H49-$E49-$G49-FIXED_COST -> -16480.202 | N49: 20 | O49: =$N49*HRS_PER_BED_CARROT*WEEKS*(1+DIM_PCT_CARROT)^$N49 -> 982.7766 | P49: =Labor!$H$7+Labor!$H$9 -> 4294.0463 | Q49: =$O49+$P49 -> 5276.8228 | R49: =MAX(0,$Q49-FARMER_HOURS) -> 4556.8228 | S49: =MIN($Q49,FARMER_HOURS)*FARMER_WAGE+IF(LABOR_MODE=1,$R49,ROUNDUP($R49/TEMP_HOURS_PER_WORKER,0)*TEMP_HOURS_PER_WORKER)*TEMP_WAGE -> 104104.84 | T49: =IF($N49=0,"",$S49-$S48) -> 1248.366 | U49: =IF($N49=0,"",$T49+FERT_CARROT) -> 1688.366 | V49: =IF($N49=0,"",PRICE_CARROT-$U49) -> 405.63402
N50: 21 | O50: =$N50*HRS_PER_BED_CARROT*WEEKS*(1+DIM_PCT_CARROT)^$N50 -> 1057.7133 | P50: =Labor!$H$7+Labor!$H$9 -> 4294.0463 | Q50: =$O50+$P50 -> 5351.7596 | R50: =MAX(0,$Q50-FARMER_HOURS) -> 4631.7596 | S50: =MIN($Q50,FARMER_HOURS)*FARMER_WAGE+IF(LABOR_MODE=1,$R50,ROUNDUP($R50/TEMP_HOURS_PER_WORKER,0)*TEMP_HOURS_PER_WORKER)*TEMP_WAGE -> 105405.75 | T50: =IF($N50=0,"",$S50-$S49) -> 1300.9014 | U50: =IF($N50=0,"",$T50+FERT_CARROT) -> 1740.9014 | V50: =IF($N50=0,"",PRICE_CARROT-$U50) -> 353.09862
A51: Mesclun — standalone | N51: Mesclun — at the optimum
A52: q (beds) | B52: Labor hrs | C52: Farmer hrs | D52: Temp hrs | E52: Labor $ | F52: Blended $/hr | G52: Fertilizer $ | H52: Revenue $ | I52: MC labor $/bed | J52: MC total $/bed | K52: Price − MC | L52: Standalone profit | N52: q (beds) | O52: This crop hrs | P52: Other crops hrs | Q52: Total farm hrs | R52: Temp hrs | S52: Total farm labor $ | T52: MC labor $/bed | U52: MC total $/bed | V52: Price − MC
A53: 0 | B53: {=INDEX(Labor!$D$5:$D$36,$A53+1)} -> 0 | C53: =MIN($B53,FARMER_HOURS) -> 0 | D53: =MAX(0,$B53-FARMER_HOURS) -> 0 | E53: =$C53*FARMER_WAGE+IF(LABOR_MODE=1,$D53,ROUNDUP($D53/TEMP_HOURS_PER_WORKER,0)*TEMP_HOURS_PER_WORKER)*TEMP_WAGE -> 0 | F53: =IF($B53=0,0,$E53/$B53) -> 0 | G53: =$A53*FERT_MESCLUN -> 0 | H53: =$A53*PRICE_MESCLUN -> 0 | I53: =IF($A53=0,"",$E53-$E52) | J53: =IF($A53=0,"",$I53+FERT_MESCLUN) | K53: =IF($A53=0,"",PRICE_MESCLUN-$J53) | L53: =$H53-$E53-$G53-FIXED_COST -> -20000 | N53: 0 | O53: =$N53*HRS_PER_BED_MESCLUN*WEEKS*(1+DIM_PCT_MESCLUN)^$N53 -> 0 | P53: =Labor!$H$7+Labor!$H$8 -> 3317.1448 | Q53: =$O53+$P53 -> 3317.1448 | R53: =MAX(0,$Q53-FARMER_HOURS) -> 2597.1448 | S53: =MIN($Q53,FARMER_HOURS)*FARMER_WAGE+IF(LABOR_MODE=1,$R53,ROUNDUP($R53/TEMP_HOURS_PER_WORKER,0)*TEMP_HOURS_PER_WORKER)*TEMP_WAGE -> 70084.834 | T53: =IF($N53=0,"",$S53-$S52) | U53: =IF($N53=0,"",$T53+FERT_MESCLUN) | V53: =IF($N53=0,"",PRICE_MESCLUN-$U53)
A54: 1 | B54: {=INDEX(Labor!$D$5:$D$36,$A54+1)} -> 45.5625 | C54: =MIN($B54,FARMER_HOURS) -> 45.5625 | D54: =MAX(0,$B54-FARMER_HOURS) -> 0 | E54: =$C54*FARMER_WAGE+IF(LABOR_MODE=1,$D54,ROUNDUP($D54/TEMP_HOURS_PER_WORKER,0)*TEMP_HOURS_PER_WORKER)*TEMP_WAGE -> 1581.93 | F54: =IF($B54=0,0,$E54/$B54) -> 34.72 | G54: =$A54*FERT_MESCLUN -> 880 | H54: =$A54*PRICE_MESCLUN -> 2700 | I54: =IF($A54=0,"",$E54-$E53) -> 1581.93 | J54: =IF($A54=0,"",$I54+FERT_MESCLUN) -> 2461.93 | K54: =IF($A54=0,"",PRICE_MESCLUN-$J54) -> 238.07 | L54: =$H54-$E54-$G54-FIXED_COST -> -19761.93 | N54: 1 | O54: =$N54*HRS_PER_BED_MESCLUN*WEEKS*(1+DIM_PCT_MESCLUN)^$N54 -> 45.5625 | P54: =Labor!$H$7+Labor!$H$8 -> 3317.1448 | Q54: =$O54+$P54 -> 3362.7073 | R54: =MAX(0,$Q54-FARMER_HOURS) -> 2642.7073 | S54: =MIN($Q54,FARMER_HOURS)*FARMER_WAGE+IF(LABOR_MODE=1,$R54,ROUNDUP($R54/TEMP_HOURS_PER_WORKER,0)*TEMP_HOURS_PER_WORKER)*TEMP_WAGE -> 70875.799 | T54: =IF($N54=0,"",$S54-$S53) -> 790.965 | U54: =IF($N54=0,"",$T54+FERT_MESCLUN) -> 1670.965 | V54: =IF($N54=0,"",PRICE_MESCLUN-$U54) -> 1029.035
A55: 2 | B55: {=INDEX(Labor!$D$5:$D$36,$A55+1)} -> 92.264062 | C55: =MIN($B55,FARMER_HOURS) -> 92.264062 | D55: =MAX(0,$B55-FARMER_HOURS) -> 0 | E55: =$C55*FARMER_WAGE+IF(LABOR_MODE=1,$D55,ROUNDUP($D55/TEMP_HOURS_PER_WORKER,0)*TEMP_HOURS_PER_WORKER)*TEMP_WAGE -> 3203.4082 | F55: =IF($B55=0,0,$E55/$B55) -> 34.72 | G55: =$A55*FERT_MESCLUN -> 1760 | H55: =$A55*PRICE_MESCLUN -> 5400 | I55: =IF($A55=0,"",$E55-$E54) -> 1621.4782 | J55: =IF($A55=0,"",$I55+FERT_MESCLUN) -> 2501.4782 | K55: =IF($A55=0,"",PRICE_MESCLUN-$J55) -> 198.52175 | L55: =$H55-$E55-$G55-FIXED_COST -> -19563.408 | N55: 2 | O55: =$N55*HRS_PER_BED_MESCLUN*WEEKS*(1+DIM_PCT_MESCLUN)^$N55 -> 92.264062 | P55: =Labor!$H$7+Labor!$H$8 -> 3317.1448 | Q55: =$O55+$P55 -> 3409.4089 | R55: =MAX(0,$Q55-FARMER_HOURS) -> 2689.4089 | S55: =MIN($Q55,FARMER_HOURS)*FARMER_WAGE+IF(LABOR_MODE=1,$R55,ROUNDUP($R55/TEMP_HOURS_PER_WORKER,0)*TEMP_HOURS_PER_WORKER)*TEMP_WAGE -> 71686.538 | T55: =IF($N55=0,"",$S55-$S54) -> 810.73912 | U55: =IF($N55=0,"",$T55+FERT_MESCLUN) -> 1690.7391 | V55: =IF($N55=0,"",PRICE_MESCLUN-$U55) -> 1009.2609
A56: 3 | B56: {=INDEX(Labor!$D$5:$D$36,$A56+1)} -> 140.12604 | C56: =MIN($B56,FARMER_HOURS) -> 140.12604 | D56: =MAX(0,$B56-FARMER_HOURS) -> 0 | E56: =$C56*FARMER_WAGE+IF(LABOR_MODE=1,$D56,ROUNDUP($D56/TEMP_HOURS_PER_WORKER,0)*TEMP_HOURS_PER_WORKER)*TEMP_WAGE -> 4865.1763 | F56: =IF($B56=0,0,$E56/$B56) -> 34.72 | G56: =$A56*FERT_MESCLUN -> 2640 | H56: =$A56*PRICE_MESCLUN -> 8100 | I56: =IF($A56=0,"",$E56-$E55) -> 1661.768 | J56: =IF($A56=0,"",$I56+FERT_MESCLUN) -> 2541.768 | K56: =IF($A56=0,"",PRICE_MESCLUN-$J56) -> 158.23197 | L56: =$H56-$E56-$G56-FIXED_COST -> -19405.176 | N56: 3 | O56: =$N56*HRS_PER_BED_MESCLUN*WEEKS*(1+DIM_PCT_MESCLUN)^$N56 -> 140.12604 | P56: =Labor!$H$7+Labor!$H$8 -> 3317.1448 | Q56: =$O56+$P56 -> 3457.2709 | R56: =MAX(0,$Q56-FARMER_HOURS) -> 2737.2709 | S56: =MIN($Q56,FARMER_HOURS)*FARMER_WAGE+IF(LABOR_MODE=1,$R56,ROUNDUP($R56/TEMP_HOURS_PER_WORKER,0)*TEMP_HOURS_PER_WORKER)*TEMP_WAGE -> 72517.422 | T56: =IF($N56=0,"",$S56-$S55) -> 830.88401 | U56: =IF($N56=0,"",$T56+FERT_MESCLUN) -> 1710.884 | V56: =IF($N56=0,"",PRICE_MESCLUN-$U56) -> 989.11599
...

Sheet Optimization
A1: Optimization — Bed Allocation
A3: 1. Decision variables (Solver changing cells, shown in blue)
A4: Crop | B4: Beds | C4: Bed cap | D4: Cap status
A5: Tomatoes | B5: 10 | C5: 20 | D5: =IF($B5<=$C5,"OK","VIOLATED") -> OK
A6: Carrots | B6: 20 | C6: 0 | D6: =IF($B6<=$C6,"OK","VIOLATED") -> VIOLATED
A7: Mesclun | B7: 30 | C7: 0 | D7: =IF($B7<=$C7,"OK","VIOLATED") -> VIOLATED
A8: Total beds | B8: =SUM($B$5:$B$7) -> 60 | C8: =TOTAL_BEDS -> 64 | D8: =IF($B8<=$C8,"OK","VIOLATED") -> OK
A10: 2. Labor & capacity
A11: Total labor hours | B11: =Labor!$H$10 -> 5276.8228
A12: Temp workers required | B12: =Labor!$H$13 -> 3.1644603 | C12: =TEMP_WORKERS_MAX -> 4 | D12: =IF($B12<=$C12,"OK","VIOLATED") -> OK
A13: Temp workers billed | B13: =Labor!$H$14 -> 3.1644603
A14: Blended labor rate ($/hr) | B14: =Labor!$H$19 -> 19.728698
A15: Labor costing mode | B15: =IF(LABOR_MODE=1,"Fractional temp hours","Whole workers (step cost)") -> Fractional temp hours
A17: 3. Season profit (Solver objective cell = B22)
A18: Revenue | B18: =$B$5*PRICE_TOMATO+$B$6*PRICE_CARROT+$B$7*PRICE_MESCLUN -> 210880
A19: Labor cost | B19: =-Labor!$H$18 -> -104104.84
A20: Fertilizer cost | B20: =-($B$5*FERT_TOMATO+$B$6*FERT_CARROT+$B$7*FERT_MESCLUN) -> -44000
A21: Fixed cost | B21: =-FIXED_COST -> -20000
A22: Season profit | B22: =SUM($B$18:$B$21) -> 42775.155
A24: 4. Standalone P ≈ MC crossing point (crop alone on the farm; MC is NOT assumed monotonic)
A25: Crop | B25: Crossing q (last q before P first drops below MC) | C25: MC total at crossing q | D25: Last q where P ≥ MC | E25: MC monotonically rising?
A26: Tomatoes | B26: =IF(COUNTIF(Cost!$K$6:$K$25,"<0")=0,BED_CAP_TOMATO,_xlfn.MINIFS(Cost!$A$6:$A$25,Cost!$K$6:$K$25,"<0")-1) -> 10 | C26: {=INDEX(Cost!$J$5:$J$25,$B26+1)} -> 8248.1149 | D26: {=SUMPRODUCT(MAX((Cost!$K$6:$K$25>=0)*Cost!$A$6:$A$25))} -> 10 | E26: {=IF(SUMPRODUCT(--(Cost!$J$7:$J$25<Cost!$J$6:$J$24))=0,"Yes","No")} -> No
A27: Carrots | B27: =IF(COUNTIF(Cost!$K$30:$K$49,"<0")=0,BED_CAP_CARROT,_xlfn.MINIFS(Cost!$A$30:$A$49,Cost!$K$30:$K$49,"<0")-1) -> 10 | C27: {=INDEX(Cost!$J$29:$J$49,$B27+1)} -> 2065.3692 | D27: {=SUMPRODUCT(MAX((Cost!$K$30:$K$49>=0)*Cost!$A$30:$A$49))} -> 20 | E27: {=IF(SUMPRODUCT(--(Cost!$J$31:$J$49<Cost!$J$30:$J$48))=0,"Yes","No")} -> No
A28: Mesclun | B28: =IF(COUNTIF(Cost!$K$54:$K$83,"<0")=0,BED_CAP_MESCLUN,_xlfn.MINIFS(Cost!$A$54:$A$83,Cost!$K$54:$K$83,"<0")-1) -> 6 | C28: {=INDEX(Cost!$J$53:$J$83,$B28+1)} -> 2667.2111 | D28: {=SUMPRODUCT(MAX((Cost!$K$54:$K$83>=0)*Cost!$A$54:$A$83))} -> 30 | E28: {=IF(SUMPRODUCT(--(Cost!$J$55:$J$83<Cost!$J$54:$J$82))=0,"Yes","No")} -> No
A29: Note: standalone crossings are below the farm optimum because a lone crop consumes the farmer's own $34.72/hr hours first. At full farm scale the marginal hour costs $17.36, lowering MC and making it pay to run carrots and mesclun to their caps.
A30: 5. Shadow price of a bed cap (profit gain from relaxing the cap by one bed, at the optimum)
A31: Crop | B31: Bed cap | C31: Beds used | D31: Cap binding? | E31: Shadow price $/bed
A32: Tomatoes | B32: =BED_CAP_TOMATO -> 20 | C32: =$B$5 -> 10 | D32: =IF($C32>=$B32,"Yes","No") -> No | E32: =IF($D32="No",0,MAX(0,INDEX(Cost!$V$5:$V$26,BED_CAP_TOMATO+2))) -> 0
A33: Carrots | B33: =BED_CAP_CARROT -> 20 | C33: =$B$6 -> 20 | D33: =IF($C33>=$B33,"Yes","No") -> Yes | E33: =IF($D33="No",0,MAX(0,INDEX(Cost!$V$29:$V$50,BED_CAP_CARROT+2))) -> 353.09862
A34: Mesclun | B34: =BED_CAP_MESCLUN -> 30 | C34: =$B$7 -> 30 | D34: =IF($C34>=$B34,"Yes","No") -> Yes | E34: =IF($D34="No",0,MAX(0,INDEX(Cost!$V$53:$V$84,BED_CAP_MESCLUN+2))) -> 246.5745
A37: 6. Solver setup (run in Excel desktop — Data ▸ Solver)
A38: Set Objective | B38: $B$22 (Season profit)
A39: To | B39: Max
A40: By Changing Variable Cells | B40: $B$5:$B$7 (Tomatoes, Carrots, Mesclun beds)
A41: Solving Method | B41: GRG Nonlinear
A42: Constraint 1 | B42: $B$5:$B$7 = integer
A43: Constraint 2 | B43: $B$5:$B$7 >= 0
A44: Constraint 3 | B44: $B$5 <= $C$5 (tomato bed cap, 20)
A45: Constraint 4 | B45: $B$6 <= $C$6 (carrot bed cap, 20)
A46: Constraint 5 | B46: $B$7 <= $C$7 (mesclun bed cap, 30)
...

Sheet Checks
A1: Validation & Acceptance Checks
A2: ="Labor costing mode: "&Optimization!$B$15 -> Labor costing mode: Fractional temp hours
A4: A. Hand check — spec reproduction step 3
A5: Check | B5: Hand value | C5: Model value | D5: Delta | E5: Result
A6: LABOR_HRS_TOMATO(1) = 1 × 2.50 × 36 × 1.10 hrs | B6: =1*2.5*36*1.1 -> 99 | C6: =Labor!$B$6 -> 99 | D6: =$C$6-$B$6 -> 0 | E6: =IF(ROUND($D$6,6)=0,"PASS","FAIL") -> PASS
A8: B. Published check figures — spec reproduction step 7 (exact match required)
A9: Check figure | B9: Published | C9: Model | D9: Delta | E9: Result
A10: Optimal beds — Tomatoes | B10: 10 | C10: =Optimization!$B$5 -> 10 | D10: =$C10-$B10 -> 0 | E10: =IF(ROUND($D10,2)=0,"PASS","FAIL") -> PASS
A11: Optimal beds — Carrots | B11: 20 | C11: =Optimization!$B$6 -> 20 | D11: =$C11-$B11 -> 0 | E11: =IF(ROUND($D11,2)=0,"PASS","FAIL") -> PASS
A12: Optimal beds — Mesclun | B12: 30 | C12: =Optimization!$B$7 -> 30 | D12: =$C12-$B12 -> 0 | E12: =IF(ROUND($D12,2)=0,"PASS","FAIL") -> PASS
A13: Season profit | B13: 42762 | C13: =Optimization!$B$22 -> 42775.155 | D13: =$C13-$B13 -> 13.155388 | E13: =IF(ROUND($D13,2)=0,"PASS","FAIL") -> FAIL
A15: C. Constraint checks — spec reproduction step 9
A16: Constraint | B16: Limit | C16: Actual | D16: Slack | E16: Result
A17: Tomato beds ≤ bed cap | B17: =BED_CAP_TOMATO -> 20 | C17: =Optimization!$B$5 -> 10 | D17: =$B17-$C17 -> 10 | E17: =IF($C17<=$B17,"SATISFIED","VIOLATED") -> SATISFIED
A18: Carrot beds ≤ bed cap | B18: =BED_CAP_CARROT -> 20 | C18: =Optimization!$B$6 -> 20 | D18: =$B18-$C18 -> 0 | E18: =IF($C18<=$B18,"SATISFIED","VIOLATED") -> SATISFIED
A19: Mesclun beds ≤ bed cap | B19: =BED_CAP_MESCLUN -> 30 | C19: =Optimization!$B$7 -> 30 | D19: =$B19-$C19 -> 0 | E19: =IF($C19<=$B19,"SATISFIED","VIOLATED") -> SATISFIED
A20: Total beds ≤ 64 | B20: =TOTAL_BEDS -> 64 | C20: =Optimization!$B$8 -> 60 | D20: =$B20-$C20 -> 4 | E20: =IF($C20<=$B20,"SATISFIED","VIOLATED") -> SATISFIED
A21: Temp workers ≤ 4 | B21: =TEMP_WORKERS_MAX -> 4 | C21: =Optimization!$B$12 -> 3.1644603 | D21: =$B21-$C21 -> 0.83553969 | E21: =IF($C21<=$B21,"SATISFIED","VIOLATED") -> SATISFIED
A23: D. Integrity checks — spec reproduction step 8
A24: Check | B24: Expected | C24: Model | D24: Delta | E24: Result
A25: Error cells (#REF!, #DIV/0!, #NAME?, etc.) across all calc ranges | B25: 0 | C25: {=SUMPRODUCT(--ISERROR(Labor!$B$5:$D$36))+SUMPRODUCT(--ISERROR(Labor!$H$4:$H$19))+SUMPRODUCT(--ISERROR(Cost!$B$5:$L$25))+SUMPRODUCT(--ISERROR(Cost!$B$29:$L$49))+SUMPRODUCT(--ISERROR(Cost!$B$53:$L$83))+SUMPRODUCT(--ISERROR(Cost!$O$5:$V$26))+SUMPRODUCT(--ISERROR(Cost!$O$29:$V$50))+SUMPRODUCT(--ISERROR(Cost!$O$53:$V$84))+SUMPRODUCT(--ISERROR(Optimization!$B$8:$D$8))+SUMPRODUCT(--ISERROR(Optimization!$C$5:$D$7))+SUMPRODUCT(--ISERROR(Optimization!$B$11:$B$15))+SUMPRODUCT(--ISERROR(Optimization!$B$18:$B$22))+SUMPRODUCT(--ISERROR(Optimization!$B$26:$E$28))+SUMPRODUCT(--ISERROR(Optimization!$B$32:$E$34))} -> 0 | D25: =$C25-$B25 -> 0 | E25: =IF($C25=$B25,"PASS","FAIL") -> PASS
A26: Calculated cells that are NOT formulas (pasted values) | B26: 0 | C26: {=SUMPRODUCT(--NOT(_xlfn.ISFORMULA(Labor!$B$5:$D$36)))+SUMPRODUCT(--NOT(_xlfn.ISFORMULA(Labor!$H$4:$H$19)))+SUMPRODUCT(--NOT(_xlfn.ISFORMULA(Cost!$B$5:$L$25)))+SUMPRODUCT(--NOT(_xlfn.ISFORMULA(Cost!$B$29:$L$49)))+SUMPRODUCT(--NOT(_xlfn.ISFORMULA(Cost!$B$53:$L$83)))+SUMPRODUCT(--NOT(_xlfn.ISFORMULA(Cost!$O$5:$V$26)))+SUMPRODUCT(--NOT(_xlfn.ISFORMULA(Cost!$O$29:$V$50)))+SUMPRODUCT(--NOT(_xlfn.ISFORMULA(Cost!$O$53:$V$84)))+SUMPRODUCT(--NOT(_xlfn.ISFORMULA(Optimization!$B$8:$D$8)))+SUMPRODUCT(--NOT(_xlfn.ISFORMULA(Optimization!$C$5:$D$7)))+SUMPRODUCT(--NOT(_xlfn.ISFORMULA(Optimization!$B$11:$B$15)))+SUMPRODUCT(--NOT(_xlfn.ISFORMULA(Optimization!$B$18:$B$22)))+SUMPRODUCT(--NOT(_xlfn.ISFORMULA(Optimization!$B$26:$E$28)))+SUMPRODUCT(--NOT(_xlfn.ISFORMULA(Optimization!$B$32:$E$34)))} -> 3 | D26: =$C26-$B26 -> 3 | E26: =IF($C26=$B26,"PASS","FAIL") -> FAIL
A28: E. Overall
A29: All checks passing? | B29: =IF(AND(COUNTIF($E$6,"FAIL")=0,COUNTIF($E$10:$E$13,"FAIL")=0,COUNTIF($E$17:$E$21,"VIOLATED")=0,COUNTIF($E$25:$E$26,"FAIL")=0),"ALL PASS","SEE FAILURES ABOVE") -> SEE FAILURES ABOVE
